Workbook

Sheet Forecast
A1: Personal Financial Forecast — Mitch
A2: Generated: April 15, 2026 | Starting Balance: $3,534.77
A4: Date | B4: Description | C4: Amount ($) | D4: Balance ($) | E4: Note | F4: Low Balance?
A5: 46127 | B5: Opening Balance | D5: 3534.77
A6: 46128 | B6: Car Payment | C6: -481.33 | D6: =D5+C6 -> 3053.44 | F6: =IF(D6<500,"⚠ LOW","OK") -> OK
A7: 46131 | B7: Groceries | C7: -100 | D7: =D6+C7 -> 2953.44 | F7: =IF(D7<500,"⚠ LOW","OK") -> OK
A8: 46138 | B8: USI | C8: -37.5 | D8: =D7+C8 -> 2915.94 | F8: =IF(D8<500,"⚠ LOW","OK") -> OK
A9: 46138 | B9: Groceries | C9: -100 | D9: =D8+C9 -> 2815.94 | F9: =IF(D9<500,"⚠ LOW","OK") -> OK
A10: 46141 | B10: Unemployment | C10: 2636.51 | D10: =D9+C10 -> 5452.45 | F10: =IF(D10<500,"⚠ LOW","OK") -> OK
A11: MAY 2026
A12: 46143 | B12: Lifetime | C12: -169 | D12: =D11+C12 -> -169 | F12: =IF(D12<500,"⚠ LOW","OK") -> ⚠ LOW
A13: 46143 | B13: Mortgage | C13: -1763.75 | D13: =D12+C13 -> -1932.75 | F13: =IF(D13<500,"⚠ LOW","OK") -> ⚠ LOW
A14: 46144 | B14: GamePass | C14: -10.88 | D14: =D13+C14 -> -1943.63 | F14: =IF(D14<500,"⚠ LOW","OK") -> ⚠ LOW
A15: 46145 | B15: Groceries | C15: -100 | D15: =D14+C15 -> -2043.63 | F15: =IF(D15<500,"⚠ LOW","OK") -> ⚠ LOW
A16: 46148 | B16: Pet Insurance | C16: -20.96 | D16: =D15+C16 -> -2064.59 | F16: =IF(D16<500,"⚠ LOW","OK") -> ⚠ LOW
A17: 46152 | B17: Groceries | C17: -100 | D17: =D16+C17 -> -2164.59 | F17: =IF(D17<500,"⚠ LOW","OK") -> ⚠ LOW
A18: 46155 | B18: Unemployment | C18: 2636.51 | D18: =D17+C18 -> 471.92 | F18: =IF(D18<500,"⚠ LOW","OK") -> ⚠ LOW
A19: 46155 | B19: Utility Bill | C19: -79.5 | D19: =D18+C19 -> 392.42 | F19: =IF(D19<500,"⚠ LOW","OK") -> ⚠ LOW
A20: 46158 | B20: Car Payment | C20: -481.33 | D20: =D19+C20 -> -88.91 | F20: =IF(D20<500,"⚠ LOW","OK") -> ⚠ LOW
A21: 46159 | B21: Groceries | C21: -100 | D21: =D20+C21 -> -188.91 | F21: =IF(D21<500,"⚠ LOW","OK") -> ⚠ LOW
A22: 46166 | B22: Groceries | C22: -100 | D22: =D21+C22 -> -288.91 | F22: =IF(D22<500,"⚠ LOW","OK") -> ⚠ LOW
A23: 46168 | B23: USI | C23: -37.5 | D23: =D22+C23 -> -326.41 | F23: =IF(D23<500,"⚠ LOW","OK") -> ⚠ LOW
... A25: 46173 | B25: Groceries | C25: -100 | D25: =D24+C25 -> 2210.1 | F25: =IF(D25<500,"⚠ LOW","OK") -> OK
A26: JUNE 2026
A27: 46174 | B27: Lifetime | C27: -169 | D27: =D26+C27 -> -169 | F27: =IF(D27<500,"⚠ LOW","OK") -> ⚠ LOW
A28: 46174 | B28: Mortgage | C28: -1763.75 | D28: =D27+C28 -> -1932.75 | F28: =IF(D28<500,"⚠ LOW","OK") -> ⚠ LOW
A29: 46175 | B29: GamePass | C29: -10.88 | D29: =D28+C29 -> -1943.63 | F29: =IF(D29<500,"⚠ LOW","OK") -> ⚠ LOW
A30: 46179 | B30: Pet Insurance | C30: -20.96 | D30: =D29+C30 -> -1964.59 | F30: =IF(D30<500,"⚠ LOW","OK") -> ⚠ LOW
A31: 46180 | B31: Groceries | C31: -100 | D31: =D30+C31 -> -2064.59 | F31: =IF(D31<500,"⚠ LOW","OK") -> ⚠ LOW
A32: 46183 | B32: Unemployment | C32: 2636.51 | D32: =D31+C32 -> 571.92 | F32: =IF(D32<500,"⚠ LOW","OK") -> OK
A33: 46186 | B33: Utility Bill | C33: -79.5 | D33: =D32+C33 -> 492.42 | F33: =IF(D33<500,"⚠ LOW","OK") -> ⚠ LOW
A34: 46187 | B34: Groceries | C34: -100 | D34: =D33+C34 -> 392.42 | F34: =IF(D34<500,"⚠ LOW","OK") -> ⚠ LOW
A35: 46189 | B35: Car Payment | C35: -481.33 | D35: =D34+C35 -> -88.91 | F35: =IF(D35<500,"⚠ LOW","OK") -> ⚠ LOW
A36: 46194 | B36: Groceries | C36: -100 | D36: =D35+C36 -> -188.91 | F36: =IF(D36<500,"⚠ LOW","OK") -> ⚠ LOW
A37: 46197 | B37: Unemployment | C37: 2636.51 | D37: =D36+C37 -> 2447.6 | F37: =IF(D37<500,"⚠ LOW","OK") -> OK
A38: 46199 | B38: USI | C38: -37.5 | D38: =D37+C38 -> 2410.1 | F38: =IF(D38<500,"⚠ LOW","OK") -> OK
A39: 46201 | B39: Groceries | C39: -100 | D39: =D38+C39 -> 2310.1 | F39: =IF(D39<500,"⚠ LOW","OK") -> OK
A40: JULY 2026
A41: 46204 | B41: Lifetime | C41: -169 | D41: =D40+C41 -> -169 | F41: =IF(D41<500,"⚠ LOW","OK") -> ⚠ LOW
A42: 46204 | B42: Mortgage | C42: -1763.75 | D42: =D41+C42 -> -1932.75 | F42: =IF(D42<500,"⚠ LOW","OK") -> ⚠ LOW
...

Sheet Balance Chart
A1: Date | B1: Balance
A2: 46127 | B2: =Forecast!D5 -> 3534.77
A3: 46128 | B3: =Forecast!D6 -> 3053.44
A4: 46131 | B4: =Forecast!D7 -> 2953.44
A5: 46138 | B5: =Forecast!D8 -> 2915.94
A6: 46138 | B6: =Forecast!D9 -> 2815.94
A7: 46141 | B7: =Forecast!D10 -> 5452.45
A8: 46143 | B8: =Forecast!D12 -> -169
A9: 46143 | B9: =Forecast!D13 -> -1932.75
A10: 46144 | B10: =Forecast!D14 -> -1943.63
A11: 46145 | B11: =Forecast!D15 -> -2043.63
A12: 46148 | B12: =Forecast!D16 -> -2064.59
A13: 46152 | B13: =Forecast!D17 -> -2164.59
A14: 46155 | B14: =Forecast!D18 -> 471.92
A15: 46155 | B15: =Forecast!D19 -> 392.42
A16: 46158 | B16: =Forecast!D20 -> -88.91
A17: 46159 | B17: =Forecast!D21 -> -188.91
A18: 46166 | B18: =Forecast!D22 -> -288.91
A19: 46168 | B19: =Forecast!D23 -> -326.41
... A21: 46173 | B21: =Forecast!D25 -> 2210.1
A22: 46174 | B22: =Forecast!D27 -> -169
A23: 46174 | B23: =Forecast!D28 -> -1932.75
A24: 46175 | B24: =Forecast!D29 -> -1943.63
A25: 46179 | B25: =Forecast!D30 -> -1964.59
A26: 46180 | B26: =Forecast!D31 -> -2064.59
A27: 46183 | B27: =Forecast!D32 -> 571.92
A28: 46186 | B28: =Forecast!D33 -> 492.42
A29: 46187 | B29: =Forecast!D34 -> 392.42
A30: 46189 | B30: =Forecast!D35 -> -88.91
A31: 46194 | B31: =Forecast!D36 -> -188.91
A32: 46197 | B32: =Forecast!D37 -> 2447.6
A33: 46199 | B33: =Forecast!D38 -> 2410.1
A34: 46201 | B34: =Forecast!D39 -> 2310.1
A35: 46204 | B35: =Forecast!D41 -> -169
A36: 46204 | B36: =Forecast!D42 -> -1932.75
A37: 46205 | B37: =Forecast!D43 -> -1943.63
A38: 46208 | B38: =Forecast!D44 -> -2043.63
A39: 46209 | B39: =Forecast!D45 -> -2064.59
A40: 46211 | B40: =Forecast!D46 -> 571.92
A41: 46215 | B41: =Forecast!D47 -> 471.92
...

Sheet Assumptions
A1: Known Recurring Expenses & Income
A3: Item | B3: Schedule | C3: Amount ($)
A4: Unemployment | B4: Every other Wednesday | C4: 2636.51
A5: Mortgage | B5: 1st of month | C5: -1763.75
A6: Lifetime | B6: 1st of month | C6: -169
A7: GamePass | B7: 2nd of month | C7: -10.88
A8: Pet Insurance | B8: 6th of month | C8: -20.96
A9: Utility Bill | B9: 13th of month | C9: -79.5
A10: Car Payment | B10: 16th of month | C10: -481.33
A11: USI | B11: 26th of month | C11: -37.5
A12: Groceries | B12: Weekly (every Sunday) | C12: -100
